[2022-04-11 14:16:46,234] {taskinstance.py:1043} INFO - Dependencies all met for <TaskInstance: openDataETL.transform manual__2022-04-11T14:11:30.743562+00:00 [queued]>
[2022-04-11 14:16:46,306] {taskinstance.py:1043} INFO - Dependencies all met for <TaskInstance: openDataETL.transform manual__2022-04-11T14:11:30.743562+00:00 [queued]>
[2022-04-11 14:16:46,320] {taskinstance.py:1249} INFO - 
--------------------------------------------------------------------------------
[2022-04-11 14:16:46,322] {taskinstance.py:1250} INFO - Starting attempt 2 of 3
[2022-04-11 14:16:46,323] {taskinstance.py:1251} INFO - 
--------------------------------------------------------------------------------
[2022-04-11 14:16:46,379] {taskinstance.py:1270} INFO - Executing <Task(PythonOperator): transform> on 2022-04-11 14:11:30.743562+00:00
[2022-04-11 14:16:46,390] {standard_task_runner.py:52} INFO - Started process 5357 to run task
[2022-04-11 14:16:46,410] {standard_task_runner.py:79} INFO - Running: ['***', 'tasks', 'run', 'openDataETL', 'transform', 'manual__2022-04-11T14:11:30.743562+00:00', '--job-id', '34', '--raw', '--subdir', 'DAGS_FOLDER/try.py', '--cfg-path', '/tmp/tmpbmxjjmlt', '--error-file', '/tmp/tmpagyf5l0h']
[2022-04-11 14:16:46,414] {standard_task_runner.py:80} INFO - Job 34: Subtask transform
[2022-04-11 14:16:46,637] {logging_mixin.py:109} INFO - Running <TaskInstance: openDataETL.transform manual__2022-04-11T14:11:30.743562+00:00 [running]> on host 474cd328f92b
[2022-04-11 14:16:46,941] {taskinstance.py:1448} INFO - Exporting the following env vars:
AIRFLOW_CTX_DAG_OWNER=***
AIRFLOW_CTX_DAG_ID=openDataETL
AIRFLOW_CTX_TASK_ID=transform
AIRFLOW_CTX_EXECUTION_DATE=2022-04-11T14:11:30.743562+00:00
AIRFLOW_CTX_DAG_RUN_ID=manual__2022-04-11T14:11:30.743562+00:00
[2022-04-11 14:16:47,000] {taskinstance.py:1774} ERROR - Task failed with exception
Traceback (most recent call last):
  File "/home/airflow/.local/lib/python3.7/site-packages/airflow/operators/python.py", line 174, in execute
    return_value = self.execute_callable()
  File "/home/airflow/.local/lib/python3.7/site-packages/airflow/operators/python.py", line 188, in execute_callable
    return self.python_callable(*self.op_args, **self.op_kwargs)
  File "/opt/airflow/dags/try.py", line 52, in transform
    data_frame = json.loads(extract_data_string)
  File "/usr/local/lib/python3.7/json/__init__.py", line 341, in loads
    raise TypeError(f'the JSON object must be str, bytes or bytearray, '
TypeError: the JSON object must be str, bytes or bytearray, not NoneType
[2022-04-11 14:16:47,097] {taskinstance.py:1288} INFO - Marking task as UP_FOR_RETRY. dag_id=openDataETL, task_id=transform, execution_date=20220411T141130, start_date=20220411T141646, end_date=20220411T141647
[2022-04-11 14:16:47,203] {standard_task_runner.py:98} ERROR - Failed to execute job 34 for task transform (the JSON object must be str, bytes or bytearray, not NoneType; 5357)
[2022-04-11 14:16:47,237] {local_task_job.py:154} INFO - Task exited with return code 1
[2022-04-11 14:16:47,532] {local_task_job.py:264} INFO - 0 downstream tasks scheduled from follow-on schedule check
