[2022-04-11 14:14:35,721] {taskinstance.py:1043} INFO - Dependencies all met for <TaskInstance: openDataETL.extract manual__2022-04-11T14:14:28.895377+00:00 [queued]>
[2022-04-11 14:14:35,798] {taskinstance.py:1043} INFO - Dependencies all met for <TaskInstance: openDataETL.extract manual__2022-04-11T14:14:28.895377+00:00 [queued]>
[2022-04-11 14:14:35,802] {taskinstance.py:1249} INFO - 
--------------------------------------------------------------------------------
[2022-04-11 14:14:35,804] {taskinstance.py:1250} INFO - Starting attempt 1 of 3
[2022-04-11 14:14:35,805] {taskinstance.py:1251} INFO - 
--------------------------------------------------------------------------------
[2022-04-11 14:14:35,888] {taskinstance.py:1270} INFO - Executing <Task(PythonOperator): extract> on 2022-04-11 14:14:28.895377+00:00
[2022-04-11 14:14:35,903] {standard_task_runner.py:52} INFO - Started process 5221 to run task
[2022-04-11 14:14:35,911] {standard_task_runner.py:79} INFO - Running: ['***', 'tasks', 'run', 'openDataETL', 'extract', 'manual__2022-04-11T14:14:28.895377+00:00', '--job-id', '30', '--raw', '--subdir', 'DAGS_FOLDER/try.py', '--cfg-path', '/tmp/tmpm7y0lpp4', '--error-file', '/tmp/tmp6pc6t7zt']
[2022-04-11 14:14:35,922] {standard_task_runner.py:80} INFO - Job 30: Subtask extract
[2022-04-11 14:14:36,122] {logging_mixin.py:109} INFO - Running <TaskInstance: openDataETL.extract manual__2022-04-11T14:14:28.895377+00:00 [running]> on host 474cd328f92b
[2022-04-11 14:14:36,447] {taskinstance.py:1448} INFO - Exporting the following env vars:
AIRFLOW_CTX_DAG_OWNER=***
AIRFLOW_CTX_DAG_ID=openDataETL
AIRFLOW_CTX_TASK_ID=extract
AIRFLOW_CTX_EXECUTION_DATE=2022-04-11T14:14:28.895377+00:00
AIRFLOW_CTX_DAG_RUN_ID=manual__2022-04-11T14:14:28.895377+00:00
[2022-04-11 14:14:38,216] {taskinstance.py:1774} ERROR - Task failed with exception
Traceback (most recent call last):
  File "/home/airflow/.local/lib/python3.7/site-packages/airflow/operators/python.py", line 174, in execute
    return_value = self.execute_callable()
  File "/home/airflow/.local/lib/python3.7/site-packages/airflow/operators/python.py", line 188, in execute_callable
    return self.python_callable(*self.op_args, **self.op_kwargs)
  File "/opt/airflow/dags/try.py", line 43, in extract
    df_all.to_csv('/log/df_all.csv')
  File "/home/airflow/.local/lib/python3.7/site-packages/pandas/core/generic.py", line 3482, in to_csv
    storage_options=storage_options,
  File "/home/airflow/.local/lib/python3.7/site-packages/pandas/io/formats/format.py", line 1105, in to_csv
    csv_formatter.save()
  File "/home/airflow/.local/lib/python3.7/site-packages/pandas/io/formats/csvs.py", line 243, in save
    storage_options=self.storage_options,
  File "/home/airflow/.local/lib/python3.7/site-packages/pandas/io/common.py", line 707, in get_handle
    newline="",
FileNotFoundError: [Errno 2] No such file or directory: '/log/df_all.csv'
[2022-04-11 14:14:38,269] {taskinstance.py:1288} INFO - Marking task as UP_FOR_RETRY. dag_id=openDataETL, task_id=extract, execution_date=20220411T141428, start_date=20220411T141435, end_date=20220411T141438
[2022-04-11 14:14:38,327] {standard_task_runner.py:98} ERROR - Failed to execute job 30 for task extract ([Errno 2] No such file or directory: '/log/df_all.csv'; 5221)
[2022-04-11 14:14:38,353] {local_task_job.py:154} INFO - Task exited with return code 1
[2022-04-11 14:14:38,478] {local_task_job.py:264} INFO - 0 downstream tasks scheduled from follow-on schedule check
