[2022-04-11 14:16:03,232] {taskinstance.py:1043} INFO - Dependencies all met for <TaskInstance: openDataETL.transform manual__2022-04-11T14:15:49.853087+00:00 [queued]>
[2022-04-11 14:16:03,289] {taskinstance.py:1043} INFO - Dependencies all met for <TaskInstance: openDataETL.transform manual__2022-04-11T14:15:49.853087+00:00 [queued]>
[2022-04-11 14:16:03,292] {taskinstance.py:1249} INFO - 
--------------------------------------------------------------------------------
[2022-04-11 14:16:03,294] {taskinstance.py:1250} INFO - Starting attempt 1 of 3
[2022-04-11 14:16:03,295] {taskinstance.py:1251} INFO - 
--------------------------------------------------------------------------------
[2022-04-11 14:16:03,343] {taskinstance.py:1270} INFO - Executing <Task(PythonOperator): transform> on 2022-04-11 14:15:49.853087+00:00
[2022-04-11 14:16:03,353] {standard_task_runner.py:52} INFO - Started process 5305 to run task
[2022-04-11 14:16:03,362] {standard_task_runner.py:79} INFO - Running: ['***', 'tasks', 'run', 'openDataETL', 'transform', 'manual__2022-04-11T14:15:49.853087+00:00', '--job-id', '33', '--raw', '--subdir', 'DAGS_FOLDER/try.py', '--cfg-path', '/tmp/tmpw8q330uy', '--error-file', '/tmp/tmpugncnj02']
[2022-04-11 14:16:03,365] {standard_task_runner.py:80} INFO - Job 33: Subtask transform
[2022-04-11 14:16:03,515] {logging_mixin.py:109} INFO - Running <TaskInstance: openDataETL.transform manual__2022-04-11T14:15:49.853087+00:00 [running]> on host 474cd328f92b
[2022-04-11 14:16:03,678] {taskinstance.py:1448} INFO - Exporting the following env vars:
AIRFLOW_CTX_DAG_OWNER=***
AIRFLOW_CTX_DAG_ID=openDataETL
AIRFLOW_CTX_TASK_ID=transform
AIRFLOW_CTX_EXECUTION_DATE=2022-04-11T14:15:49.853087+00:00
AIRFLOW_CTX_DAG_RUN_ID=manual__2022-04-11T14:15:49.853087+00:00
[2022-04-11 14:16:03,696] {taskinstance.py:1774} ERROR - Task failed with exception
Traceback (most recent call last):
  File "/home/airflow/.local/lib/python3.7/site-packages/airflow/operators/python.py", line 174, in execute
    return_value = self.execute_callable()
  File "/home/airflow/.local/lib/python3.7/site-packages/airflow/operators/python.py", line 188, in execute_callable
    return self.python_callable(*self.op_args, **self.op_kwargs)
  File "/opt/airflow/dags/try.py", line 52, in transform
    data_frame = json.loads(extract_data_string)
  File "/usr/local/lib/python3.7/json/__init__.py", line 341, in loads
    raise TypeError(f'the JSON object must be str, bytes or bytearray, '
TypeError: the JSON object must be str, bytes or bytearray, not NoneType
[2022-04-11 14:16:03,737] {taskinstance.py:1288} INFO - Marking task as UP_FOR_RETRY. dag_id=openDataETL, task_id=transform, execution_date=20220411T141549, start_date=20220411T141603, end_date=20220411T141603
[2022-04-11 14:16:03,787] {standard_task_runner.py:98} ERROR - Failed to execute job 33 for task transform (the JSON object must be str, bytes or bytearray, not NoneType; 5305)
[2022-04-11 14:16:03,817] {local_task_job.py:154} INFO - Task exited with return code 1
[2022-04-11 14:16:03,922] {local_task_job.py:264} INFO - 0 downstream tasks scheduled from follow-on schedule check
