[2022-04-11 14:22:28,069] {taskinstance.py:1043} INFO - Dependencies all met for <TaskInstance: openDataETL.load manual__2022-04-11T14:12:30.549249+00:00 [queued]>
[2022-04-11 14:22:28,162] {taskinstance.py:1043} INFO - Dependencies all met for <TaskInstance: openDataETL.load manual__2022-04-11T14:12:30.549249+00:00 [queued]>
[2022-04-11 14:22:28,164] {taskinstance.py:1249} INFO - 
--------------------------------------------------------------------------------
[2022-04-11 14:22:28,166] {taskinstance.py:1250} INFO - Starting attempt 2 of 4
[2022-04-11 14:22:28,168] {taskinstance.py:1251} INFO - 
--------------------------------------------------------------------------------
[2022-04-11 14:22:28,297] {taskinstance.py:1270} INFO - Executing <Task(PythonOperator): load> on 2022-04-11 14:12:30.549249+00:00
[2022-04-11 14:22:28,335] {standard_task_runner.py:52} INFO - Started process 5733 to run task
[2022-04-11 14:22:28,346] {standard_task_runner.py:79} INFO - Running: ['***', 'tasks', 'run', 'openDataETL', 'load', 'manual__2022-04-11T14:12:30.549249+00:00', '--job-id', '53', '--raw', '--subdir', 'DAGS_FOLDER/try.py', '--cfg-path', '/tmp/tmpm9xh_egi', '--error-file', '/tmp/tmpn6foo6p6']
[2022-04-11 14:22:28,372] {standard_task_runner.py:80} INFO - Job 53: Subtask load
[2022-04-11 14:22:29,007] {logging_mixin.py:109} INFO - Running <TaskInstance: openDataETL.load manual__2022-04-11T14:12:30.549249+00:00 [running]> on host 474cd328f92b
[2022-04-11 14:22:29,670] {taskinstance.py:1448} INFO - Exporting the following env vars:
AIRFLOW_CTX_DAG_OWNER=***
AIRFLOW_CTX_DAG_ID=openDataETL
AIRFLOW_CTX_TASK_ID=load
AIRFLOW_CTX_EXECUTION_DATE=2022-04-11T14:12:30.549249+00:00
AIRFLOW_CTX_DAG_RUN_ID=manual__2022-04-11T14:12:30.549249+00:00
[2022-04-11 14:22:29,742] {taskinstance.py:1774} ERROR - Task failed with exception
Traceback (most recent call last):
  File "/home/airflow/.local/lib/python3.7/site-packages/airflow/operators/python.py", line 174, in execute
    return_value = self.execute_callable()
  File "/home/airflow/.local/lib/python3.7/site-packages/airflow/operators/python.py", line 188, in execute_callable
    return self.python_callable(*self.op_args, **self.op_kwargs)
  File "/opt/airflow/dags/try.py", line 56, in load
    total_order_value = json.loads(total_value_string)
  File "/usr/local/lib/python3.7/json/__init__.py", line 341, in loads
    raise TypeError(f'the JSON object must be str, bytes or bytearray, '
TypeError: the JSON object must be str, bytes or bytearray, not NoneType
[2022-04-11 14:22:29,895] {taskinstance.py:1288} INFO - Marking task as UP_FOR_RETRY. dag_id=openDataETL, task_id=load, execution_date=20220411T141230, start_date=20220411T142228, end_date=20220411T142229
[2022-04-11 14:22:30,091] {standard_task_runner.py:98} ERROR - Failed to execute job 53 for task load (the JSON object must be str, bytes or bytearray, not NoneType; 5733)
[2022-04-11 14:22:30,142] {local_task_job.py:154} INFO - Task exited with return code 1
[2022-04-11 14:22:30,749] {local_task_job.py:264} INFO - 0 downstream tasks scheduled from follow-on schedule check
