[2022-04-11 14:13:37,710] {taskinstance.py:1043} INFO - Dependencies all met for <TaskInstance: openDataETL.extract manual__2022-04-11T14:13:31.305288+00:00 [queued]>
[2022-04-11 14:13:37,766] {taskinstance.py:1043} INFO - Dependencies all met for <TaskInstance: openDataETL.extract manual__2022-04-11T14:13:31.305288+00:00 [queued]>
[2022-04-11 14:13:37,767] {taskinstance.py:1249} INFO - 
--------------------------------------------------------------------------------
[2022-04-11 14:13:37,769] {taskinstance.py:1250} INFO - Starting attempt 1 of 3
[2022-04-11 14:13:37,771] {taskinstance.py:1251} INFO - 
--------------------------------------------------------------------------------
[2022-04-11 14:13:37,833] {taskinstance.py:1270} INFO - Executing <Task(PythonOperator): extract> on 2022-04-11 14:13:31.305288+00:00
[2022-04-11 14:13:37,846] {standard_task_runner.py:52} INFO - Started process 5162 to run task
[2022-04-11 14:13:37,866] {standard_task_runner.py:79} INFO - Running: ['***', 'tasks', 'run', 'openDataETL', 'extract', 'manual__2022-04-11T14:13:31.305288+00:00', '--job-id', '29', '--raw', '--subdir', 'DAGS_FOLDER/try.py', '--cfg-path', '/tmp/tmpuoyzao9q', '--error-file', '/tmp/tmpc8_n_1jd']
[2022-04-11 14:13:37,869] {standard_task_runner.py:80} INFO - Job 29: Subtask extract
[2022-04-11 14:13:38,082] {logging_mixin.py:109} INFO - Running <TaskInstance: openDataETL.extract manual__2022-04-11T14:13:31.305288+00:00 [running]> on host 474cd328f92b
[2022-04-11 14:13:38,356] {taskinstance.py:1448} INFO - Exporting the following env vars:
AIRFLOW_CTX_DAG_OWNER=***
AIRFLOW_CTX_DAG_ID=openDataETL
AIRFLOW_CTX_TASK_ID=extract
AIRFLOW_CTX_EXECUTION_DATE=2022-04-11T14:13:31.305288+00:00
AIRFLOW_CTX_DAG_RUN_ID=manual__2022-04-11T14:13:31.305288+00:00
[2022-04-11 14:13:39,665] {taskinstance.py:1774} ERROR - Task failed with exception
Traceback (most recent call last):
  File "/home/airflow/.local/lib/python3.7/site-packages/airflow/operators/python.py", line 174, in execute
    return_value = self.execute_callable()
  File "/home/airflow/.local/lib/python3.7/site-packages/airflow/operators/python.py", line 188, in execute_callable
    return self.python_callable(*self.op_args, **self.op_kwargs)
  File "/opt/airflow/dags/try.py", line 43, in extract
    df_all.to_csv('./log/df_all.csv')
  File "/home/airflow/.local/lib/python3.7/site-packages/pandas/core/generic.py", line 3482, in to_csv
    storage_options=storage_options,
  File "/home/airflow/.local/lib/python3.7/site-packages/pandas/io/formats/format.py", line 1105, in to_csv
    csv_formatter.save()
  File "/home/airflow/.local/lib/python3.7/site-packages/pandas/io/formats/csvs.py", line 243, in save
    storage_options=self.storage_options,
  File "/home/airflow/.local/lib/python3.7/site-packages/pandas/io/common.py", line 707, in get_handle
    newline="",
FileNotFoundError: [Errno 2] No such file or directory: './log/df_all.csv'
[2022-04-11 14:13:39,755] {taskinstance.py:1288} INFO - Marking task as UP_FOR_RETRY. dag_id=openDataETL, task_id=extract, execution_date=20220411T141331, start_date=20220411T141337, end_date=20220411T141339
[2022-04-11 14:13:39,858] {standard_task_runner.py:98} ERROR - Failed to execute job 29 for task extract ([Errno 2] No such file or directory: './log/df_all.csv'; 5162)
[2022-04-11 14:13:39,897] {local_task_job.py:154} INFO - Task exited with return code 1
[2022-04-11 14:13:40,126] {local_task_job.py:264} INFO - 0 downstream tasks scheduled from follow-on schedule check
