[2022-04-11 14:22:28,374] {taskinstance.py:1043} INFO - Dependencies all met for <TaskInstance: openDataETL.extract manual__2022-04-11T14:12:30.549249+00:00 [queued]>
[2022-04-11 14:22:28,490] {taskinstance.py:1043} INFO - Dependencies all met for <TaskInstance: openDataETL.extract manual__2022-04-11T14:12:30.549249+00:00 [queued]>
[2022-04-11 14:22:28,493] {taskinstance.py:1249} INFO - 
--------------------------------------------------------------------------------
[2022-04-11 14:22:28,494] {taskinstance.py:1250} INFO - Starting attempt 3 of 5
[2022-04-11 14:22:28,503] {taskinstance.py:1251} INFO - 
--------------------------------------------------------------------------------
[2022-04-11 14:22:28,662] {taskinstance.py:1270} INFO - Executing <Task(PythonOperator): extract> on 2022-04-11 14:12:30.549249+00:00
[2022-04-11 14:22:28,690] {standard_task_runner.py:52} INFO - Started process 5735 to run task
[2022-04-11 14:22:28,726] {standard_task_runner.py:79} INFO - Running: ['***', 'tasks', 'run', 'openDataETL', 'extract', 'manual__2022-04-11T14:12:30.549249+00:00', '--job-id', '54', '--raw', '--subdir', 'DAGS_FOLDER/try.py', '--cfg-path', '/tmp/tmpm1ch8hcp', '--error-file', '/tmp/tmpupsgwk6y']
[2022-04-11 14:22:28,734] {standard_task_runner.py:80} INFO - Job 54: Subtask extract
[2022-04-11 14:22:29,310] {logging_mixin.py:109} INFO - Running <TaskInstance: openDataETL.extract manual__2022-04-11T14:12:30.549249+00:00 [running]> on host 474cd328f92b
[2022-04-11 14:22:29,937] {taskinstance.py:1448} INFO - Exporting the following env vars:
AIRFLOW_CTX_DAG_OWNER=***
AIRFLOW_CTX_DAG_ID=openDataETL
AIRFLOW_CTX_TASK_ID=extract
AIRFLOW_CTX_EXECUTION_DATE=2022-04-11T14:12:30.549249+00:00
AIRFLOW_CTX_DAG_RUN_ID=manual__2022-04-11T14:12:30.549249+00:00
[2022-04-11 14:22:33,899] {local_task_job.py:212} WARNING - State of this instance has been externally set to restarting. Terminating instance.
[2022-04-11 14:22:33,913] {process_utils.py:124} INFO - Sending Signals.SIGTERM to group 5735. PIDs of all processes in the group: [5735]
[2022-04-11 14:22:33,917] {process_utils.py:75} INFO - Sending the signal Signals.SIGTERM to group 5735
[2022-04-11 14:22:33,920] {taskinstance.py:1430} ERROR - Received SIGTERM. Terminating subprocesses.
[2022-04-11 14:22:33,984] {taskinstance.py:1774} ERROR - Task failed with exception
Traceback (most recent call last):
  File "/home/airflow/.local/lib/python3.7/site-packages/airflow/operators/python.py", line 174, in execute
    return_value = self.execute_callable()
  File "/home/airflow/.local/lib/python3.7/site-packages/airflow/operators/python.py", line 188, in execute_callable
    return self.python_callable(*self.op_args, **self.op_kwargs)
  File "/opt/airflow/dags/try.py", line 37, in extract
    url, header=1, quoting=csv.QUOTE_NONE, encoding='utf-8')
  File "/home/airflow/.local/lib/python3.7/site-packages/pandas/util/_decorators.py", line 311, in wrapper
    return func(*args, **kwargs)
  File "/home/airflow/.local/lib/python3.7/site-packages/pandas/io/parsers/readers.py", line 586, in read_csv
    return _read(filepath_or_buffer, kwds)
  File "/home/airflow/.local/lib/python3.7/site-packages/pandas/io/parsers/readers.py", line 482, in _read
    parser = TextFileReader(filepath_or_buffer, **kwds)
  File "/home/airflow/.local/lib/python3.7/site-packages/pandas/io/parsers/readers.py", line 811, in __init__
    self._engine = self._make_engine(self.engine)
  File "/home/airflow/.local/lib/python3.7/site-packages/pandas/io/parsers/readers.py", line 1040, in _make_engine
    return mapping[engine](self.f, **self.options)  # type: ignore[call-arg]
  File "/home/airflow/.local/lib/python3.7/site-packages/pandas/io/parsers/c_parser_wrapper.py", line 51, in __init__
    self._open_handles(src, kwds)
  File "/home/airflow/.local/lib/python3.7/site-packages/pandas/io/parsers/base_parser.py", line 229, in _open_handles
    errors=kwds.get("encoding_errors", "strict"),
  File "/home/airflow/.local/lib/python3.7/site-packages/pandas/io/common.py", line 614, in get_handle
    storage_options=storage_options,
  File "/home/airflow/.local/lib/python3.7/site-packages/pandas/io/common.py", line 317, in _get_filepath_or_buffer
    reader = BytesIO(req.read())
  File "/usr/local/lib/python3.7/http/client.py", line 478, in read
    s = self._safe_read(self.length)
  File "/usr/local/lib/python3.7/http/client.py", line 628, in _safe_read
    chunk = self.fp.read(min(amt, MAXAMOUNT))
  File "/usr/local/lib/python3.7/socket.py", line 589, in readinto
    return self._sock.recv_into(b)
  File "/usr/local/lib/python3.7/ssl.py", line 1071, in recv_into
    return self.read(nbytes, buffer)
  File "/usr/local/lib/python3.7/ssl.py", line 929, in read
    return self._sslobj.read(len, buffer)
  File "/home/airflow/.local/lib/python3.7/site-packages/airflow/models/taskinstance.py", line 1432, in signal_handler
    raise AirflowException("Task received SIGTERM signal")
airflow.exceptions.AirflowException: Task received SIGTERM signal
[2022-04-11 14:22:34,172] {taskinstance.py:1288} INFO - Marking task as UP_FOR_RETRY. dag_id=openDataETL, task_id=extract, execution_date=20220411T141230, start_date=20220411T142228, end_date=20220411T142234
[2022-04-11 14:22:34,419] {standard_task_runner.py:98} ERROR - Failed to execute job 54 for task extract (Task received SIGTERM signal; 5735)
[2022-04-11 14:22:34,482] {process_utils.py:70} INFO - Process psutil.Process(pid=5735, status='terminated', exitcode=1, started='14:22:27') (5735) terminated with exit code 1
