[2022-04-11 14:19:25,875] {taskinstance.py:1043} INFO - Dependencies all met for <TaskInstance: openDataETL.load manual__2022-04-11T14:14:59.610040+00:00 [queued]>
[2022-04-11 14:19:26,722] {taskinstance.py:1043} INFO - Dependencies all met for <TaskInstance: openDataETL.load manual__2022-04-11T14:14:59.610040+00:00 [queued]>
[2022-04-11 14:19:26,739] {taskinstance.py:1249} INFO - 
--------------------------------------------------------------------------------
[2022-04-11 14:19:26,749] {taskinstance.py:1250} INFO - Starting attempt 1 of 3
[2022-04-11 14:19:26,762] {taskinstance.py:1251} INFO - 
--------------------------------------------------------------------------------
[2022-04-11 14:19:27,001] {taskinstance.py:1270} INFO - Executing <Task(PythonOperator): load> on 2022-04-11 14:14:59.610040+00:00
[2022-04-11 14:19:27,119] {standard_task_runner.py:52} INFO - Started process 5520 to run task
[2022-04-11 14:19:27,139] {standard_task_runner.py:79} INFO - Running: ['***', 'tasks', 'run', 'openDataETL', 'load', 'manual__2022-04-11T14:14:59.610040+00:00', '--job-id', '37', '--raw', '--subdir', 'DAGS_FOLDER/try.py', '--cfg-path', '/tmp/tmpft0vpmbv', '--error-file', '/tmp/tmp7n4zt6bq']
[2022-04-11 14:19:27,163] {standard_task_runner.py:80} INFO - Job 37: Subtask load
[2022-04-11 14:19:28,415] {logging_mixin.py:109} INFO - Running <TaskInstance: openDataETL.load manual__2022-04-11T14:14:59.610040+00:00 [running]> on host 474cd328f92b
[2022-04-11 14:19:31,180] {taskinstance.py:1448} INFO - Exporting the following env vars:
AIRFLOW_CTX_DAG_OWNER=***
AIRFLOW_CTX_DAG_ID=openDataETL
AIRFLOW_CTX_TASK_ID=load
AIRFLOW_CTX_EXECUTION_DATE=2022-04-11T14:14:59.610040+00:00
AIRFLOW_CTX_DAG_RUN_ID=manual__2022-04-11T14:14:59.610040+00:00
[2022-04-11 14:19:31,395] {taskinstance.py:1774} ERROR - Task failed with exception
Traceback (most recent call last):
  File "/home/airflow/.local/lib/python3.7/site-packages/airflow/operators/python.py", line 174, in execute
    return_value = self.execute_callable()
  File "/home/airflow/.local/lib/python3.7/site-packages/airflow/operators/python.py", line 188, in execute_callable
    return self.python_callable(*self.op_args, **self.op_kwargs)
  File "/opt/airflow/dags/try.py", line 56, in load
    total_order_value = json.loads(total_value_string)
  File "/usr/local/lib/python3.7/json/__init__.py", line 341, in loads
    raise TypeError(f'the JSON object must be str, bytes or bytearray, '
TypeError: the JSON object must be str, bytes or bytearray, not NoneType
[2022-04-11 14:19:31,879] {taskinstance.py:1288} INFO - Marking task as UP_FOR_RETRY. dag_id=openDataETL, task_id=load, execution_date=20220411T141459, start_date=20220411T141925, end_date=20220411T141931
[2022-04-11 14:19:32,563] {standard_task_runner.py:98} ERROR - Failed to execute job 37 for task load (the JSON object must be str, bytes or bytearray, not NoneType; 5520)
[2022-04-11 14:19:32,994] {local_task_job.py:154} INFO - Task exited with return code 1
[2022-04-11 14:19:34,313] {local_task_job.py:264} INFO - 0 downstream tasks scheduled from follow-on schedule check
