[2022-04-11 14:19:26,837] {taskinstance.py:1043} INFO - Dependencies all met for <TaskInstance: openDataETL.transform manual__2022-04-11T14:14:28.895377+00:00 [queued]>
[2022-04-11 14:19:27,447] {taskinstance.py:1043} INFO - Dependencies all met for <TaskInstance: openDataETL.transform manual__2022-04-11T14:14:28.895377+00:00 [queued]>
[2022-04-11 14:19:27,462] {taskinstance.py:1249} INFO - 
--------------------------------------------------------------------------------
[2022-04-11 14:19:27,515] {taskinstance.py:1250} INFO - Starting attempt 1 of 3
[2022-04-11 14:19:27,533] {taskinstance.py:1251} INFO - 
--------------------------------------------------------------------------------
[2022-04-11 14:19:28,294] {taskinstance.py:1270} INFO - Executing <Task(PythonOperator): transform> on 2022-04-11 14:14:28.895377+00:00
[2022-04-11 14:19:28,339] {standard_task_runner.py:52} INFO - Started process 5522 to run task
[2022-04-11 14:19:28,504] {standard_task_runner.py:79} INFO - Running: ['***', 'tasks', 'run', 'openDataETL', 'transform', 'manual__2022-04-11T14:14:28.895377+00:00', '--job-id', '38', '--raw', '--subdir', 'DAGS_FOLDER/try.py', '--cfg-path', '/tmp/tmpzfqi5uiz', '--error-file', '/tmp/tmpqzqfgksw']
[2022-04-11 14:19:28,555] {standard_task_runner.py:80} INFO - Job 38: Subtask transform
[2022-04-11 14:19:29,968] {logging_mixin.py:109} INFO - Running <TaskInstance: openDataETL.transform manual__2022-04-11T14:14:28.895377+00:00 [running]> on host 474cd328f92b
[2022-04-11 14:19:31,870] {taskinstance.py:1448} INFO - Exporting the following env vars:
AIRFLOW_CTX_DAG_OWNER=***
AIRFLOW_CTX_DAG_ID=openDataETL
AIRFLOW_CTX_TASK_ID=transform
AIRFLOW_CTX_EXECUTION_DATE=2022-04-11T14:14:28.895377+00:00
AIRFLOW_CTX_DAG_RUN_ID=manual__2022-04-11T14:14:28.895377+00:00
[2022-04-11 14:19:32,023] {taskinstance.py:1774} ERROR - Task failed with exception
Traceback (most recent call last):
  File "/home/airflow/.local/lib/python3.7/site-packages/airflow/operators/python.py", line 174, in execute
    return_value = self.execute_callable()
  File "/home/airflow/.local/lib/python3.7/site-packages/airflow/operators/python.py", line 188, in execute_callable
    return self.python_callable(*self.op_args, **self.op_kwargs)
  File "/opt/airflow/dags/try.py", line 47, in transform
    df_all = pd.read_csv('/opt/airflow/logs/df_all.csv')
  File "/home/airflow/.local/lib/python3.7/site-packages/pandas/util/_decorators.py", line 311, in wrapper
    return func(*args, **kwargs)
  File "/home/airflow/.local/lib/python3.7/site-packages/pandas/io/parsers/readers.py", line 586, in read_csv
    return _read(filepath_or_buffer, kwds)
  File "/home/airflow/.local/lib/python3.7/site-packages/pandas/io/parsers/readers.py", line 482, in _read
    parser = TextFileReader(filepath_or_buffer, **kwds)
  File "/home/airflow/.local/lib/python3.7/site-packages/pandas/io/parsers/readers.py", line 811, in __init__
    self._engine = self._make_engine(self.engine)
  File "/home/airflow/.local/lib/python3.7/site-packages/pandas/io/parsers/readers.py", line 1040, in _make_engine
    return mapping[engine](self.f, **self.options)  # type: ignore[call-arg]
  File "/home/airflow/.local/lib/python3.7/site-packages/pandas/io/parsers/c_parser_wrapper.py", line 51, in __init__
    self._open_handles(src, kwds)
  File "/home/airflow/.local/lib/python3.7/site-packages/pandas/io/parsers/base_parser.py", line 229, in _open_handles
    errors=kwds.get("encoding_errors", "strict"),
  File "/home/airflow/.local/lib/python3.7/site-packages/pandas/io/common.py", line 707, in get_handle
    newline="",
FileNotFoundError: [Errno 2] No such file or directory: '/opt/airflow/logs/df_all.csv'
[2022-04-11 14:19:32,690] {taskinstance.py:1288} INFO - Marking task as UP_FOR_RETRY. dag_id=openDataETL, task_id=transform, execution_date=20220411T141428, start_date=20220411T141926, end_date=20220411T141932
[2022-04-11 14:19:33,389] {standard_task_runner.py:98} ERROR - Failed to execute job 38 for task transform ([Errno 2] No such file or directory: '/opt/airflow/logs/df_all.csv'; 5522)
[2022-04-11 14:19:33,588] {local_task_job.py:154} INFO - Task exited with return code 1
[2022-04-11 14:19:35,478] {local_task_job.py:264} INFO - 0 downstream tasks scheduled from follow-on schedule check
