[2022-04-11 14:20:25,504] {taskinstance.py:1043} INFO - Dependencies all met for <TaskInstance: openDataETL.extract manual__2022-04-11T14:14:59.610040+00:00 [queued]>
[2022-04-11 14:20:25,681] {taskinstance.py:1043} INFO - Dependencies all met for <TaskInstance: openDataETL.extract manual__2022-04-11T14:14:59.610040+00:00 [queued]>
[2022-04-11 14:20:25,687] {taskinstance.py:1249} INFO - 
--------------------------------------------------------------------------------
[2022-04-11 14:20:25,691] {taskinstance.py:1250} INFO - Starting attempt 2 of 3
[2022-04-11 14:20:25,694] {taskinstance.py:1251} INFO - 
--------------------------------------------------------------------------------
[2022-04-11 14:20:25,961] {taskinstance.py:1270} INFO - Executing <Task(PythonOperator): extract> on 2022-04-11 14:14:59.610040+00:00
[2022-04-11 14:20:25,997] {standard_task_runner.py:52} INFO - Started process 5604 to run task
[2022-04-11 14:20:26,034] {standard_task_runner.py:79} INFO - Running: ['***', 'tasks', 'run', 'openDataETL', 'extract', 'manual__2022-04-11T14:14:59.610040+00:00', '--job-id', '48', '--raw', '--subdir', 'DAGS_FOLDER/try.py', '--cfg-path', '/tmp/tmp03lr9b58', '--error-file', '/tmp/tmpyq7m6scl']
[2022-04-11 14:20:26,058] {standard_task_runner.py:80} INFO - Job 48: Subtask extract
[2022-04-11 14:20:31,460] {local_task_job.py:212} WARNING - State of this instance has been externally set to failed. Terminating instance.
[2022-04-11 14:20:31,511] {process_utils.py:124} INFO - Sending Signals.SIGTERM to group 5604. PIDs of all processes in the group: [5604]
[2022-04-11 14:20:31,515] {process_utils.py:75} INFO - Sending the signal Signals.SIGTERM to group 5604
[2022-04-11 14:20:33,705] {process_utils.py:70} INFO - Process psutil.Process(pid=5604, status='terminated', exitcode=0, started='14:20:25') (5604) terminated with exit code 0
