[2022-04-11 14:22:02,313] {taskinstance.py:1043} INFO - Dependencies all met for <TaskInstance: openDataETL.load manual__2022-04-11T14:21:53.941443+00:00 [queued]>
[2022-04-11 14:22:02,421] {taskinstance.py:1043} INFO - Dependencies all met for <TaskInstance: openDataETL.load manual__2022-04-11T14:21:53.941443+00:00 [queued]>
[2022-04-11 14:22:02,429] {taskinstance.py:1249} INFO - 
--------------------------------------------------------------------------------
[2022-04-11 14:22:02,443] {taskinstance.py:1250} INFO - Starting attempt 1 of 3
[2022-04-11 14:22:02,446] {taskinstance.py:1251} INFO - 
--------------------------------------------------------------------------------
[2022-04-11 14:22:02,519] {taskinstance.py:1270} INFO - Executing <Task(PythonOperator): load> on 2022-04-11 14:21:53.941443+00:00
[2022-04-11 14:22:02,537] {standard_task_runner.py:52} INFO - Started process 5692 to run task
[2022-04-11 14:22:02,562] {standard_task_runner.py:79} INFO - Running: ['***', 'tasks', 'run', 'openDataETL', 'load', 'manual__2022-04-11T14:21:53.941443+00:00', '--job-id', '50', '--raw', '--subdir', 'DAGS_FOLDER/try.py', '--cfg-path', '/tmp/tmpgvxe8sdm', '--error-file', '/tmp/tmppbqpfwlv']
[2022-04-11 14:22:02,570] {standard_task_runner.py:80} INFO - Job 50: Subtask load
[2022-04-11 14:22:02,849] {logging_mixin.py:109} INFO - Running <TaskInstance: openDataETL.load manual__2022-04-11T14:21:53.941443+00:00 [running]> on host 474cd328f92b
[2022-04-11 14:22:03,109] {taskinstance.py:1448} INFO - Exporting the following env vars:
AIRFLOW_CTX_DAG_OWNER=***
AIRFLOW_CTX_DAG_ID=openDataETL
AIRFLOW_CTX_TASK_ID=load
AIRFLOW_CTX_EXECUTION_DATE=2022-04-11T14:21:53.941443+00:00
AIRFLOW_CTX_DAG_RUN_ID=manual__2022-04-11T14:21:53.941443+00:00
[2022-04-11 14:22:03,140] {taskinstance.py:1774} ERROR - Task failed with exception
Traceback (most recent call last):
  File "/home/airflow/.local/lib/python3.7/site-packages/airflow/operators/python.py", line 174, in execute
    return_value = self.execute_callable()
  File "/home/airflow/.local/lib/python3.7/site-packages/airflow/operators/python.py", line 188, in execute_callable
    return self.python_callable(*self.op_args, **self.op_kwargs)
  File "/opt/airflow/dags/try.py", line 56, in load
    total_order_value = json.loads(total_value_string)
  File "/usr/local/lib/python3.7/json/__init__.py", line 341, in loads
    raise TypeError(f'the JSON object must be str, bytes or bytearray, '
TypeError: the JSON object must be str, bytes or bytearray, not NoneType
[2022-04-11 14:22:03,190] {taskinstance.py:1288} INFO - Marking task as UP_FOR_RETRY. dag_id=openDataETL, task_id=load, execution_date=20220411T142153, start_date=20220411T142202, end_date=20220411T142203
[2022-04-11 14:22:03,259] {standard_task_runner.py:98} ERROR - Failed to execute job 50 for task load (the JSON object must be str, bytes or bytearray, not NoneType; 5692)
[2022-04-11 14:22:03,300] {local_task_job.py:154} INFO - Task exited with return code 1
[2022-04-11 14:22:03,417] {local_task_job.py:264} INFO - 0 downstream tasks scheduled from follow-on schedule check
